---
layout: post
title: "Openstack Unable to enable dhcp for : there is a conflict with its current state; please check that the network and/or its subnet(s) still exist"
date: 2016-05-01
---

Right when you try to start neutron linuxbridge or dhcp-agent there can be such errors. net-list have the network and subnet listed. So why this error ?. This setup is with linux bridge. Those who are using ovs might have different table names. 

~~~
2016-05-07 16:06:32.573 985 INFO neutron.agent.dhcp_agent [req-eff3aec4-bb3a-48d7-ad53-dd9fd7428ae6 None] Synchronizing state
2016-05-07 16:06:32.597 985 INFO neutron.agent.dhcp_agent [-] DHCP agent started
2016-05-07 16:06:33.497 985 DEBUG neutron.agent.dhcp_agent [-] Calling driver for network: dc83138c-7af5-4917-8931-0149bb736083 action: enable call_driver /usr/lib/python2.7/site-packages/neutron/agent/dhcp_agent.py:119
2016-05-07 16:06:33.498 985 DEBUG neutron.agent.linux.dhcp [-] Unable to access /var/lib/neutron/dhcp/dc83138c-7af5-4917-8931-0149bb736083/pid _get_value_from_conf_file /usr/lib/python2.7/site-packages/neutron/agent/linux/dhcp.py:267
2016-05-07 16:06:33.499 985 DEBUG neutron.agent.linux.dhcp [-] DHCP port dhcp57aa2c89-eb31-5aa6-baa3-9db19f8fe78d-dc83138c-7af5-4917-8931-0149bb736083 on network dc83138c-7af5-4917-8931-0149bb736083 does not yet exist. Checking for a reserved port. setup_dhcp_port /usr/lib/python2.7/site-packages/neutron/agent/linux/dhcp.py:888
2016-05-07 16:06:33.500 985 DEBUG neutron.agent.linux.dhcp [-] DHCP port dhcp57aa2c89-eb31-5aa6-baa3-9db19f8fe78d-dc83138c-7af5-4917-8931-0149bb736083 on network dc83138c-7af5-4917-8931-0149bb736083 does not yet exist. setup_dhcp_port /usr/lib/python2.7/site-packages/neutron/agent/linux/dhcp.py:902
2016-05-07 16:06:33.498 985 DEBUG neutron.agent.linux.dhcp [-] Unable to access /var/lib/neutron/dhcp/dc83138c-7af5-4917-8931-0149bb736083/pid _get_value_from_conf_file /usr/lib/python2.7/site-packages/neutron/agent/linux/dhcp.py:267
2016-05-07 16:06:33.499 985 DEBUG neutron.agent.linux.dhcp [-] DHCP port dhcp57aa2c89-eb31-5aa6-baa3-9db19f8fe78d-dc83138c-7af5-4917-8931-0149bb736083 on network dc83138c-7af5-4917-8931-0149bb736083 does not yet exist. Checking for a reserved port. setup_dhcp_port /usr/lib/python2.7/site-packages/neutron/agent/linux/dhcp.py:888
2016-05-07 16:06:33.500 985 DEBUG neutron.agent.linux.dhcp [-] DHCP port dhcp57aa2c89-eb31-5aa6-baa3-9db19f8fe78d-dc83138c-7af5-4917-8931-0149bb736083 on network dc83138c-7af5-4917-8931-0149bb736083 does not yet exist. setup_dhcp_port /usr/lib/python2.7/site-packages/neutron/agent/linux/dhcp.py:902
2016-05-07 16:06:34.129 985 WARNING neutron.agent.dhcp_agent [-] Unable to enable dhcp for dc83138c-7af5-4917-8931-0149bb736083: there is a conflict with its current state; please check that the network and/or its subnet(s) still exist.
~~~

Checking mysql master for the dhcp port, the data is missing but `neutron net-list` shows the network and subnet added. 

~~~
mysql> select * from ports where device_owner='network:dhcp';
Empty set (0.00 sec)
~~~

Insert from backup in this case since it was missing. Take the value from mysqldump file and insert it into the table. 

~~~
INSERT INTO `ports` VALUES ('b675b38b5eba4957b55408753ea58b55','ab32b59a-922b-4ac3-b9c3-c253d3473eda','','dc83138c-7af5-4917-8931-0149bb736083','fa:16:3e:85:sd:6a',1,'ACTIVE','dhcp57aa2c89-eb31-5aa6-baa3-9db19f8fe78d-dc83138c-7af5-4917-8931-0149bb736083','network:dhcp');
~~~

~~~
select * from ports where device_owner='network:dhcp';
+----------------------------------+--------------------------------------+------+--------------------------------------+-------------------+----------------+--------+-------------------------------------------------------------------------------+--------------+
| tenant_id                        | id                                   | name | network_id                           | mac_address       | admin_state_up | status | device_id                                                                     | device_owner |
+----------------------------------+--------------------------------------+------+--------------------------------------+-------------------+----------------+--------+-------------------------------------------------------------------------------+--------------+
| b675b38b5eba4957b55408753ea58b55 | ab32b59a-922b-4ac3-b9c3-c253d3473eda |      | dc83138c-7af5-4917-8931-0149bb736083 | fa:16:3e:85:sd:6a |              1 | ACTIVE | dhcp57aa2c89-eb31-5aa6-baa3-9db19f8fe78d-dc83138c-7af5-4917-8931-0149bb736083 | network:dhcp |
+----------------------------------+--------------------------------------+------+--------------------------------------+-------------------+----------------+--------+-------------------------------------------------------------------------------+--------------+
1 rows in set (0.00 sec)
~~~

Now once you add this if the dhcp port is missing you will get below error.

~~~
2016-05-07 17:01:21.250 13133 TRACE neutron.agent.dhcp_agent     raise result
2016-05-07 17:01:21.250 13133 TRACE neutron.agent.dhcp_agent RemoteError: Remote error: PortNotFound Port ab32b59a-922b-4ac3-b9c3-c253d3473eda could not be found
~~~

Checking mysql master 

~~~
mysql> select * from ipallocations where port_id='ab32b59a-922b-4ac3-b9c3-c253d3473eda';
Empty set (0.00 sec)
~~~

Again restoring from backup of ipallocations. After this dhcp service was up . 

After the above errors linuxbridge agent was not creating up bridge because port binding was missing.  

~~~
mysql> select * from ml2_port_bindings where port_id='ab32b59a-922b-4ac3-b9c3-c253d3473eda';
Empty set (0.00 sec)
~~~

After restoring from backup linux bridge started working. So most of the time these types of error happens when mysql or any database used by openstack have incorrect data or data is all together missing. Hope this helps. :)
